Workbook

Sheet Sheet2
A1: SAMPLE NAME | B1: ANDERSON ID | C1: CLIENT | D1: FREEDOM DATE | E1: RECEIVED DATE | F1: RUN
A2: BABY.TAMILARASI (1Y|F) | B2: AND25020015503 | C2: CHIEF MINISTERS COMPREHENSIVE HEALTH INSURANCE SCHEME | D2: 45663 | E2: 20-05-2025 | F2: RUN 6
A3: MISS.MOUSIKA (11Y|F) | B3: AND25020014248 | C3: CHIEF MINISTERS COMPREHENSIVE HEALTH INSURANCE SCHEME | D3: 27-05-2025 | E3: 45843 | F3: RUN 6
A4: MASTER.SIDDHARTH (8Y|M) | B4: AND25020014496 | C4: CHIEF MINISTERS COMPREHENSIVE HEALTH INSURANCE SCHEME | D4: 28-05-2025 | E4: 26-05-2025 | F4: RUN 6
A5: BABY.YADHU NANDHAN (2Y|M) | B5: AND25020014497 | C5: CHIEF MINISTERS COMPREHENSIVE HEALTH INSURANCE SCHEME | D5: 28-05-2025 | E5: 26-05-2025 | F5: RUN 6
A6: MISS.SRI SIVASANKARI (8Y|F) | B6: AND25020014499 | C6: CHIEF MINISTERS COMPREHENSIVE HEALTH INSURANCE SCHEME | D6: 28-05-2025 | E6: 26-05-2025 | F6: RUN 6
A7: BABY.HANISHA (1Y|F) | B7: AND25020014500 | C7: CHIEF MINISTERS COMPREHENSIVE HEALTH INSURANCE SCHEME | D7: 28-05-2025 | E7: 29-05-2026 | F7: RUN 6
A8: BABY.VARSHIT (4M|M) | B8: AND25020014502 | C8: CHIEF MINISTERS COMPREHENSIVE HEALTH INSURANCE SCHEME | D8: 28-05-2025 | E8: 16-05-2025 | F8: RUN 6
A9: BABY.JESSICA (1Y|F) | B9: AND25020016089 | C9: CHIEF MINISTERS COMPREHENSIVE HEALTH INSURANCE SCHEME | D9: 45722 | E9: 29-05-2025 | F9: RUN 6
A10: MASTER.SAMARTH SHRIVAS (11Y|M) | B10: AND25750003076 | C10: DR.RAJE PATHOLOGY - MADHYA PRADESH ., | D10: 45694 | E10: 31-05-2025 | F10: RUN 6
A11: MRS.SANGEETHA G R (35Y|F) | B11: AND251R0004594 | C11: AIKYA FERTILITY AND RESEARCH CENTER - BANGALORE | D11: 45722 | E11: 45753 | F11: RUN 6
A12: MR.MRK (0Y|M) | B12: AND25630000933 | C12: ADSL | D12: 45844 | E12: 31-05-2025 | F12: RUN 6
A13: MR.ABHIJITH A (24Y|M) | B13: AND25380048667 | C13: MEITRA HOSPITAL - KOZHIKODE | D13: 45783 | E13: 45663 | F13: RUN 6
A14: MISS.KAJAL BASFORE (19Y|F) | B14: AND25020016338 | C14: DR.DEEPAK ARJUNDAS MD (MED) D.M (NEURO) FRCP | D14: 45753 | E14: 45752 | F14: RUN 6
A15: MRS.AMMU (26Y|F) | B15: AND25370007387 | C15: BALARAMAN V DM.DIP (NB) | D15: 30-05-2025 | E15: 31.05.2025 | F15: RUN 6
A16: MRS.SAVITA BAI LODHI (26Y|F) | B16: AND25AE0000101 | C16: DR. D PANKAR BANERJI – JABALPUR | D16: 22-05-2025 | E16: 23-05-2025 | F16: RUN 6
A17: MRS.SONAL PATEL (31Y|F) | B17: AND25AE0000107 | C17: DR. D PANKAR BANERJI – JABALPUR | D17: 23-05-2025 | E17: 26-05-2025 | F17: RUN 6
A18: BABY OF.NANTHINI (6D|M) | B18: AND25970002993 | C18: TINY HEARTS - THANJAVUR | D18: 28-05-2025 | E18: 28-05-2025 | F18: RUN 6
A19: MR.VAMARAJU VENKATA PHANI CHANDRA (42Y|M) | B19: AND25420001089 | C19: HEGDE HEALTHCARE PVT LTD | D19: 26-05-2025 | E19: 27-05-2025 | F19: RUN 6
A20: BABY.PRASANN T (1Y|F) | B20: AND251H0000950 | C20: A ONE HOSPITAL & IVF CLINIC- SRIKAKULAM | D20: 27-05-2025 | E20: 27-05-2025 | F20: RUN 6
A21: BABY.SUNITHA K (3Y|F) | B21: AND251H0000973 | C21: MEDICOVER HOSPITAL - SRIKAKULAM | D21: 28-05-2025 | E21: 28-05-2025 | F21: RUN 6
A22: MR.MOHAMED YASIN S(34YM) ( parents of yasna tanzim- already released report) | B22: AND25150019747 | C22: DR.SUDHA RATHNA PRABHU MBBS,DNB,PHD | D22: 28-05-2025 | E22: 29-05-2025 | F22: RUN 6
A23: MRS.NOORUL FARHANA A(26YF) ( parents of baby riya- already released report) | B23: AND25150019748 | C23: DR.SUDHA RATHNA PRABHU MBBS,DNB,PHD | D23: 28-05-2025 | E23: 29-05-2025 | F23: RUN 6
A24: MASTER.JESIN JAI (250202012) (7Y|M) | B24: AND25410006138 | C24: GERDI GUTPERLE AGASTHIYARMUNI CHILD CARE CENTRE (GGAMCCC) - NAGERCOIL | D24: 28-05-2025 | E24: 29-05-2025 | F24: RUN 6
A25: MRS.MANGALI SHIVANI (25Y|F) | B25: AND25420001140 | C25: HEGDE HEALTHCARE PVT LTD | D25: 29-05-2025 | E25: 30.05.2025 | F25: RUN 6
A26: MRS.MANGALI YADAGIRI (32Y|F) | B26: AND25420001141 | C26: HEGDE HEALTHCARE PVT LTD | D26: 29-05-2025 | E26: 30.05.2025 | F26: RUN 6
... A28: MRS.NANDHINI (30Y|F) | B28: AND25630000778 | C28: ICH EGMORE - CHENNAI | D28: 30-05-2025 | E28: 31-05-2025 | F28: RUN 6
A30: BABY.YUTHA JOEL(1YM) | B30: AND25020016549 | C30: CHIEF MINISTERS COMPREHENSIVE HEALTH INSURANCE SCHEME | D30: 45783 | E30: 45721 | F30: RUN 54A
A31: BABY.RITAI ZIDAN(2YM) | B31: AND25400009717 | C31: NAMBIYAPPAN HOSPITALS CHILD CARE CENTRE - TIRUNELVELI | D31: 45783 | F31: RUN 54A
A32: MRS.TIRUMALA SETTY RADHA - (HEG C005845)(36YF) | B32: AND25420001218 | C32: HEGDE HEALTHCARE PVT LTD | D32: 45814 | E32: 45814 | F32: RUN 54A
A33: MR.ARVAPALLY VENKATA NAGA PRASAD H/O.T.RADHA - HEGC005845(37YM) | B33: AND25420001219 | C33: HEGDE HEALTHCARE PVT LTD | D33: 45814 | E33: 45814 | F33: RUN 54A
A34: MR.YELLANURU MOHAMMED ZEELAN(37YM) | B34: AND25420001223 | C34: DR.SELF . | D34: 45814 | E34: 45753 | F34: RUN 54A
A35: MRS.SHAIK SAJIDA BANU(30YF) | B35: AND25420001222 | C35: DR.SELF . | D35: 45814 | E35: 45753 | F35: RUN 54A
A36: BABY.CHARVI DINESH(0YF) | B36: AND25630000935 | C36: DR.SUDHA RATHNA PRABHU MBBS,DNB,PH.D., | D36: 45844 | E36: 45814 | F36: RUN 54A
A37: SELVI.ABIRAMI P (11Y|F) | B37: AND25380050238 | C37: MURUGAN HOSPITAL | D37: 45844 | E37: 45844 | F37: RUN 54A
A38: MRS.SHENBAGAM (38Y|F) | B38: AND25380050239 | C38: MURUGAN HOSPITAL | D38: 45844 | E38: 45844 | F38: RUN 54A
A39: MRS.PRITIKA KAPOOR W/O. RAM RAWAT (33Y|F) | B39: AND25420001327 | C39: 9M FERTILITY BY ANKURA HOSPITAL - HYDERABAD | D39: 45844 | E39: 45875 | F39: RUN 54A
A40: MR.RAM RAWAT H/O. PRITIKA KAPOOR (35Y|M) | B40: AND25420001328 | C40: 9M FERTILITY BY ANKURA HOSPITAL - HYDERABAD | D40: 45844 | E40: 45875 | F40: RUN 54A
A41: MRS.NANDHINI (23Y|F) POC | B41: AND25360012648 | C41: SAI KRISHNA LAB - MADURAI | D41: 45694 | E41: 45753 | F41: RUN 54A
A42: MRS.SUHANA(27YF) | B42: AND251R0004284 | C42: SELF | D42: 30-05-2025 | E42: 31.05.2025 | F42: RUN 54A
...

Sheet CMC-Vellore
A1: inakaran
A2: S.No | B2: Sample_Name | C2: Gender | D2: CONDITION | E2: Gen_id | F2: Anderson Id | G2: Client | H2: TAT (30 days) | I2: Bioinfo Analysis time | J2: ANALYZE BY | K2: ANALYZE DATE | L2: PRIMARY REVIWER (PRATHEEBA/NAVEEN) | M2: FINAL REVIEW | N2: REMARK | O2: REPORT RELEASE DATE | P2: History writeup
A3: 1 | B3: MS.CHI-1(0YO) | D3: hyperinsulinemia | E3: GEN_T_2.0.spik_1149 | F3: AND-TP-166-LIB-22 | G3: CMC
A4: 2 | B4: MS.CHI-4(0YO) | D4: hyperinsulinemia | E4: GEN_T_2.0.spik_1150 | F4: AND-TP-166-LIB-23 | G4: CMC
A5: 3 | B5: MS.CHI-6(0YO) | D5: hyperinsulinemia | E5: GEN_T_2.0.spik_1151 | F5: AND-TP-166-LIB-24 | G5: CMC
A6: 4 | B6: MS.CHI-7(0YO) | D6: hyperinsulinemia | E6: GEN_T_2.0.spik_1152 | F6: AND-TP-167-LIB-25 | G6: CMC
A7: 5 | B7: MS.CHI-9(0YO) | D7: hyperinsulinemia | E7: GEN_T_2.0.spik_1153 | F7: AND-TP-167-LIB-26 | G7: CMC
A8: 6 | B8: MS.CHI-10(0YO) | D8: hyperinsulinemia | E8: GEN_T_2.0.spik_1154 | F8: AND-TP-167-LIB-27 | G8: CMC
A9: 7 | B9: MS.CHI-11(0YO) | D9: hyperinsulinemia | E9: GEN_T_2.0.spik_1156 | F9: AND-TP-167-LIB-28 | G9: CMC
A10: 8 | B10: MS.CHI-12(0YO) | D10: hyperinsulinemia | E10: GEN_T_2.0.spik_1157 | F10: AND-TP-167-LIB-29 | G10: CMC
A11: 9 | B11: MS.CHI-13(0YO) | D11: hyperinsulinemia | E11: GEN_T_2.0.spik_1158 | F11: AND-TP-167-LIB-30 | G11: CMC
A12: 10 | B12: MS.CHI-14(0YO) | D12: hyperinsulinemia | E12: GEN_T_2.0.spik_1159 | F12: AND-TP-167-LIB-31 | G12: CMC
A13: 11 | B13: MS.CHI-16(0YO) | D13: hyperinsulinemia | E13: GEN_T_2.0.spik_1160 | F13: AND-TP-167-LIB-32 | G13: CMC
A14: SURFseq- Run-5_Lane 3
A15: S.No | B15: Sample_Name | C15: Gender | D15: CONDITION | E15: Gen_id | F15: Anderson Id | G15: Client | H15: TAT (30 days) | I15: Bioinfo Analysis time | J15: ANALYZE BY | K15: ANALYZE DATE | L15: PRIMARY REVIWER (PRATHEEBA/NAVEEN) | M15: FINAL REVIEW | N15: REMARK | O15: REPORT RELEASE DATE | P15: History writeup
A16: 12 | B16: MS.CHI-19(0YO) | D16: hyperinsulinemia | E16: GEN_T_2.0.spik_1161 | F16: AND-TP-168-LIB-12 | G16: CMC
A17: 13 | B17: MS.CHI-21(0YO) | D17: hyperinsulinemia | E17: GEN_T_2.0.spik_1162 | F17: AND-TP-168-LIB-13 | G17: CMC
A18: 14 | B18: MS.CHI-24(0YO) | D18: hyperinsulinemia | E18: GEN_T_2.0.spik_1163 | F18: AND-TP-168-LIB-14 | G18: CMC
A19: 15 | B19: MS.CHI-35(0YO) | D19: hyperinsulinemia | E19: GEN_T_2.0.spik_1164 | F19: AND-TP-168-LIB-15 | G19: CMC
A20: 16 | B20: MS.CHI-36(0YO) | D20: hyperinsulinemia | E20: GEN_T_2.0.spik_1165 | F20: AND-TP-168-LIB-16 | G20: CMC
A21: 17 | B21: MS.CHI-37(0YO) | D21: hyperinsulinemia | E21: GEN_T_2.0.spik_1166 | F21: AND-TP-168-LIB-17 | G21: CMC
A22: 18 | B22: MS.CHI-38(0YO) | D22: hyperinsulinemia | E22: GEN_T_2.0.spik_1167 | F22: AND-TP-168-LIB-18 | G22: CMC
A23: 19 | B23: MS.CHI-42(0YO) | D23: hyperinsulinemia | E23: GEN_T_2.0.spik_1168 | F23: AND-TP-168-LIB-19 | G23: CMC
A24: 20 | B24: MS.CHI-58(0YO) | D24: hyperinsulinemia | E24: GEN_T_2.0.spik_1178 | F24: AND-TP-171-LIB-20 | G24: CMC
A25: 21 | B25: MS.CHI-60(0YO) | D25: hyperinsulinemia | E25: GEN_T_2.0.spik_1179 | F25: AND-TP-171-LIB-21 | G25: CMC
A26: 22 | B26: MS.CHI-61(0YO) | D26: hyperinsulinemia | E26: GEN_T_2.0.spik_1180 | F26: AND-TP-171-LIB-22 | G26: CMC
A27: 23 | B27: MS.CHI-62(0YO) | D27: hyperinsulinemia | E27: GEN_T_2.0.spik_1181 | F27: AND-TP-171-LIB-23 | G27: CMC
A28: 24 | B28: MS.CHI-63(0YO) | D28: hyperinsulinemia | E28: GEN_T_2.0.spik_1182 | F28: AND-TP-171-LIB-24 | G28: CMC
A29: SURFseq- Run-5_Lane 4
A30: S.No | B30: Sample_Name | C30: Gender | D30: CONDITION | E30: Gen_id | F30: Anderson Id | G30: Client | H30: TAT (30 days) | I30: Bioinfo Analysis time | J30: ANALYZE BY | K30: ANALYZE DATE | L30: PRIMARY REVIWER (PRATHEEBA/NAVEEN) | M30: FINAL REVIEW | N30: REMARK | O30: REPORT RELEASE DATE | P30: History writeup
A31: 25 | B31: MS.CHI-44(0YO) | D31: hyperinsulinemia | E31: GEN_T_2.0.spik_1169 | F31: AND-TP-169-17 | G31: CMC
A32: 26 | B32: MS.CHI-46(0YO) | D32: hyperinsulinemia | E32: GEN_T_2.0.spik_1170 | F32: AND-TP-169-18 | G32: CMC
A33: 27 | B33: MS.CHI-48(0YO) | D33: hyperinsulinemia | E33: GEN_T_2.0.spik_1171 | F33: AND-TP-169-19 | G33: CMC
A34: 28 | B34: MS.CHI-49(0YO) | D34: hyperinsulinemia | E34: GEN_T_2.0.spik_1155 | F34: AND-TP-169-20 | G34: CMC
A35: 29 | B35: MS.CHI-50(0YO) | D35: hyperinsulinemia | E35: GEN_T_2.0.spik_1172 | F35: AND-TP-169-21 | G35: CMC
A36: 30 | B36: MS.CHI-51(0YO) | D36: hyperinsulinemia | E36: GEN_T_2.0.spik_1173 | F36: AND-TP-170-26 | G36: CMC
A37: 31 | B37: MS.CHI-54(0YO) | D37: hyperinsulinemia | E37: GEN_T_2.0.spik_1174 | F37: AND-TP-170-27 | G37: CMC
A38: 32 | B38: MS.CHI-55(0YO) | D38: hyperinsulinemia | E38: GEN_T_2.0.spik_1175 | F38: AND-TP-170-28 | G38: CMC
A39: 33 | B39: MS.CHI-56(0YO) | D39: hyperinsulinemia | E39: GEN_T_2.0.spik_1176 | F39: AND-TP-170-29 | G39: CMC
A40: 34 | B40: MS.CHI-57(0YO) | D40: hyperinsulinemia | E40: GEN_T_2.0.spik_1177 | F40: AND-TP-170-30 | G40: CMC
...

Sheet RE-ANALYSIS
A1: f | B1: Sample_Name | C1: Test | D1: Gen_ID | E1: Anderson_ID | F1: Client | G1: RAW DATA RECEIVED DATE | H1: ANALYZE BY | I1: ANALYZE DATE | J1: REVIEWER | K1: FINAL REVIEW | L1: REMARK | M1: REPORT RELEASE DATE | N1: History writeup
A2: 1 | B2: Mr. Prathik Singh (husband of komal singh - AND25420002073) | G2: 28-07-2025 | N2: Writeup Available
A3: 2 | B3: Thiruvendhan - CMC | G3: 45755 | H3: Diwakar
A4: 3 | B4: Dhanshika_9234064 | C4: NGS Data Reanalysis | E4: AND25630002113 | F4: Dr.SUDHA RATHNA PRABHU MBBS,DNB,PH.D., | G4: 30-08-2025 | N4: Writeup Available
A5: 4 | B5: MS. NIRANJANA ( 0Y|F ) | C5: NGS Data Reanalysis | E5: AND25630002836 | F5: Dr.SUDHA RATHNA PRABHU MBBS,DNB,PH.D., | G5: 30-09-2025 | L5: Sent for review | N5: Writeup Available
A6: 5 | B6: BABY. SIDDHARTHAN ( 7M|M ) | C6: NGS Data Reanalysis | E6: AND25630003090 | F6: Dr.SUDHA RATHNA PRABHU MBBS,DNB,PH.D., | G6: 16-10-2025 | H6: Pratheeba | L6: Sent for review | N6: Writeup Available
A7: 6 | B7: karimunnisa | C7: NGS Data Reanalysis | E7: AND25420003967 | F7: Dr.DR. KAVYA REDDY . | G7: 14-10-2025 | M7: 13-11-2025 | N7: Writeup Available
A8: 7 | B8: Baby Hamirish | C8: NGS Data Reanalysis | E8: AND25630003263 | G8: 30-10-2025 | N8: History available in TRF,Writeup not available
A9: 8 | B9: hema gowrish
A10: 8 | B10: Baby M. Aadhil Sheriff | C10: NGS Data Reanalysis
A11: 9 | B11: Kavineeth | C11: NGS Data Reanalysis | F11: Dr.SUDHA RATHNA PRABHU MBBS,DNB,PH.D., | G11: 45728
A12: 10 | B12: Mr. Vara Prasad Noojella (wes done @And for couple on 29-06-2023) | C12: NGS Data Reanalysis
A13: 11 | B13: Mrs. Haritha Noojella (wes done @And for couple on 29-06-2023) | C13: NGS Data Reanalysis | F13: Hedge Healthcare Pvt Ltd
A14: 12 | B14: Baby.Divina | C14: NGS Data Reanalysis | E14: AND25630003953 | F14: Dr.SUDHA RATHNA PRABHU MBBS,DNB,PH.D.,
A15: 13 | B15: Irshad Ahmed Sait | C15: NGS Data Reanalysis | F15: Dr.SUDHA RATHNA PRABHU MBBS,DNB,PH.D.,
A16: 14 | B16: Mrs. Sapna Pal | D16: 1566 | E16: AND25100002156 | F16: : Hospital/Clinic: ANDERSON LABS - PRAYAGRAJ | H16: Diwakar / Franklin | I16: 24-12-2025 | J16: Diwakar | K16: Sent to sir | N16: Writeup Available
A17: 15 | B17: Dhashvin | F17: Dr.SUDHA RATHNA PRABHU MBBS,DNB,PH.D.,
A18: 16 | B18: Puzhalenthi
A19: 17 | B19: Master.Sharvesh Durai | E19: AND23380049769
A20: 18 | B20: Baby.Dhakshith | E20: AND26620048528
A21: 19 | B21: Mr.Kowshik Mahadev | E21: AND21380069107
A22: 20 | B22: Baby.Sakthi S | E22: AND25630002737
A23: 21 | B23: Baby of Pavithra | E23: AND25630002581
A24: 22 | B24: Arya (MR.BALAJI (42 Y 0 M 0 D Male)_MRS.SUMALATHA (32 Y 0 M 0 D Female) - first child) | G24: 13-01-2026
A25: 23 | B25: Mr. Thiagarajan [1684] | D25: GEN_T_2.0.spik_2640 | E25: AND25430001584 | H25: Sanjay | I25: 26-02-2026 | J25: Diwakar | K25: Sent to sir | L25: Report released | M25: 28/02/2026
A26: 24 | B26: Sagar
A27: 25 | B27: Nisha
A28: 26 | B28: Adyar-WES44 | C28: NGS Data Reanalysis
A29: 27 | B29: Adyar-WES42 | C29: NGS Data Reanalysis
A30: 28 | B30: Adyar-WES41 | C30: NGS Data Reanalysis
A31: 29 | B31: Baby. Iniya. B | E31: AND25630005140 | F31: ICH Egmore - Chennai
A32: 30 | B32: Mr. Sankaradoss | C32: NGS Data Reanalysis | F32: Dr.SUDHA RATHNA PRABHU MBBS,DNB,PH.D.,
A33: 31 | B33: Mrs. Raja Lakshmi | C33: NGS Data Reanalysis | F33: Dr.SUDHA RATHNA PRABHU MBBS,DNB,PH.D.,
A34: 32 | B34: Ms. Rupika Rajendran | E34: AND25370004185 | F34: ICH Egmore - Chennai | J34: diwakar | L34: reanalysis done | M34: 46085
A35: 33 | B35: Mr. Sangeeth Setty | C35: NGS Data Reanalysis | F35: Hedge Healthcare Pvt Ltd | G35: 23-04-2026 | H35: Naveen | I35: 27-04-2026 | J35: naveen | L35: Report released | M35: 46178
A36: 34 | B36: Ms. Anusha Banda | C36: NGS Data Reanalysis | F36: Hedge Healthcare Pvt Ltd | G36: 23-04-2026 | H36: Naveen | I36: 27-04-2026 | J36: naveen | L36: Report released | M36: 46178
A37: 35 | B37: Baby of Krishnaveni | C37: NGS Data Reanalysis | F37: Dr.SUDHA RATHNA PRABHU MBBS,DNB,PH.D., | J37: naveen
A38: 36 | B38: Mr. Karthick Kannan (2511038797) | E38: CBC0000001444 | F38: A4 Fertility Centre - Virugambakkam | J38: vignesh | L38: Report released | M38: 13/05/2026
A39: 39 | B39: Baby. P. Vamsi | C39: NGS Data Reanalysis | E39: AND25020009223 | F39: CHIEF MINISTERS COMPREHENSIVE HEALTH INSURANCE SCHEME
A40: 41 | B40: Mr. Pinninti Thaviti Naidu | C40: NGS Data Reanalysis | E40: AND251H0001294 | F40: Medicover Hospital - Srikakulam
...

Sheet Sheet1
A1: f
A2: S.NO | B2: Sample_Name | C2: TEST | D2: GENID | E2: Anderson Id | F2: Client | G2: TAT (30 days) | H2: Bioinfo Analysis time | J2: ANALYZE BY (DIKSHA/VAMSHI) | K2: ANALYZE DATE | L2: PRIMARY REVIWER (PRATHEEBA/NAVEEN) | M2: FINAL REVIEW | N2: REMARK | O2: REPORT RELEASE DATE | P2: History Writeup
A3: 26 | B3: MISS.SUJITHA RENY (8Y|F) | C3: WES | D3: GEN_T_2.0.spik_1070 | E3: AND25020009516 | F3: CHIEF MINISTERS COMPREHENSIVE HEALTH INSURANCE SCHEME | G3: 45817 | O3: 26-06-2025 | P3: Writeup availble
A5: SURFSeq - Run - 4 Lane - 02(Repeat samples)
A6: S.NO | B6: Sample_Name | C6: TEST | D6: GENID | E6: Anderson Id | F6: Client | G6: TAT (30 days) | H6: Bioinfo Analysis time | J6: ANALYZE BY (DIKSHA/VAMSHI) | K6: ANALYZE DATE | L6: PRIMARY REVIWER (PRATHEEBA/NAVEEN) | M6: FINAL REVIEW | N6: REMARK | O6: REPORT RELEASE DATE | P6: History Writeup
A7: 17 | B7: MS.SURUTHI ABIRAMI B (31Y|F) | C7: WES | D7: GEN_T_2.0.spik_1035A | E7: AND25630000341 | G7: 31/05/2025
A8: 24 | B8: MISS.THANIGAIVEDHA D/O SANDHYA MUTHULINGAM (30Y|F) | C8: WES | D8: GEN_T_2.0.spik_1040A | E8: AND25380023404 | F8: A4 FERTILITY CENTRE - (A UNIT OF A4 HOSPITAL) - CHENNAI | G8: 45694 | P8: Writeup available
A10: SURFSeq - Run - 4 Lane - 03
A11: S.NO | B11: Sample_Name | C11: TEST | D11: GENID | E11: Anderson Id | F11: Client | G11: TAT (30 days) | H11: Bioinfo Analysis time | J11: ANALYZE BY (DIKSHA/VAMSHI) | K11: ANALYZE DATE | L11: PRIMARY REVIWER (PRATHEEBA/NAVEEN) | M11: FINAL REVIEW | N11: REMARK | O11: REPORT RELEASE DATE | P11: History Writeup
A12: 1 | B12: MS.SURUTHI ABIRAMI B(31YF) | C12: WES | D12: GEN_T_2.0.spik_1035A | E12: AND25630000341 | F12: ADSL | G12: 31-05-2025 | J12: VAMSHI | K12: 45723
A14: SURFSeq - Run - 4 Lane - 03
A15: S.NO | B15: Sample_Name | C15: TEST | D15: GENID | E15: Anderson Id | F15: Client | G15: TAT (30 days) | H15: Bioinfo Analysis time | J15: ANALYZE BY (DIKSHA/VAMSHI) | K15: ANALYZE DATE | L15: PRIMARY REVIWER (PRATHEEBA/NAVEEN) | M15: FINAL REVIEW | N15: REMARK | O15: REPORT RELEASE DATE | P15: History Writeup
A16: 10 | B16: BABY.PENCHALA MEDHANSH (1Y|M) | C16: WES | D16: GEN_T_2.0.spik_1055 | E16: AND25630000386 | F16: DR.SUDHA RATHNA PRABHU MBBS,DNB,PHD | G16: 45812 | J16: DIKSHA | K16: 14/06/2025 | L16: PRATHEEBA | O16: 45723 | P16: Writeup available
A17: 19 | B17: MRS.GAYATHRI G (34Y|F) | C17: WES | D17: GEN_T_2.0.spik_1080 | E17: AND25020010300 | F17: DR.SUDHA RATHNA PRABHU MBBS,DNB,PHD | G17: 45817 | J17: VAMSHI | K17: 22/06/2025 | L17: PRATHEEBA | O17: 45723
A18: 20 | B18: MR.MANIKANDAN M (43Y|M) | C18: WES | D18: GEN_T_2.0.spik_1081 | E18: AND25020010303 | F18: DR.SUDHA RATHNA PRABHU MBBS,DNB,PHD | G18: 45817 | J18: VAMSHI | K18: 22/06/2025 | L18: PRATHEEBA | O18: 45723 | P18: Writeup available
A20: SURFSeq - Run - 5 Lane - 01
A21: S.NO | B21: Sample_Name | C21: TEST | D21: GENID | E21: Anderson Id | F21: Client | G21: TAT (30 days) | H21: Bioinfo Analysis time | J21: ANALYZE BY (DIKSHA/VAMSHI) | K21: ANALYZE DATE | L21: PRIMARY REVIWER (PRATHEEBA/NAVEEN) | M21: FINAL REVIEW | N21: REMARK | O21: REPORT RELEASE DATE | P21: History Writeup
A22: 1 | B22: MASTER.RUDRAV R (6M|M) | C22: WES | D22: GEN_T_2.0.spik_1085 | E22: AND25720005682 | F22: MEITRA HOSPITAL - KOZHIKODE | G22: 45936 | H22: 7 days | J22: VAMSHI | K22: 45818 | L22: NAVEEN | O22: 45967 | P22: Writeup available
A23: 2 | B23: JANISHA(11Y/F) | C23: WES | D23: GEN_T_2.0.spik_1086 | E23: AND25020010764 | F23: CHIEF MINISTERS COMPREHENSIVE HEALTH INSURANCE SCHEME | G23: 45753 | H23: 1 days | J23: VAMSHI | K23: 45814 | L23: NAVEEN | O23: 17/06/2025 | P23: Writeup available
A24: 3 | B24: MRS.SHILPA W/O KIRAN KUMAR (33YF) AF | C24: WES | D24: GEN_T_2.0.spik_AF1088 | E24: AND25910005649 | F24: GURU SCAN CENTRE - DAVANGERE | G24: 45967 | H24: 8 days | L24: PRATHEEBA | O24: 45936
A25: 4 | B25: MRS.NIDHI(29YF) POC | C25: WES | D25: GEN_T_2.0.spik_1089 | E25: AND25380028019 | F25: DR.SHALINI LALITKUMAR MS, OBG | G25: 45875 | H25: 5 days | J25: DIKSHA | K25: 13/06/2025 | O25: 23/06/2024 | P25: Writeup available
A26: 5 | B26: SANTONINO | C26: WES | D26: GEN_T_2.0.spik_1091 | E26: AND25020010765 | F26: CHIEF MINISTERS COMPREHENSIVE HEALTH INSURANCE SCHEME | G26: 45814 | H26: 3 days | J26: DIKSHA | K26: 45814 | L26: PRATHEEBA | O26: 19-06-2025 | P26: Writeup available
A27: 6 | B27: MR.PRAKASH(0YM) | C27: Male Infertility NGS panel | D27: GEN_T_2.0.spik_1112 | E27: AND25380035463 | F27: AKSHARA FERTILITY CENTRE - ANNA NAGAR | G27: - | H27: - | O27: 27-06-2025
A28: 7 | B28: BABY OF.AKANKSHA PANDEY (12D|F) - Urgent report | C28: WES | D28: GEN_T_2.0.spik_1093 | E28: AND25100000700 | F28: MOTHERLAND HOSPITAL - NOIDA | G28: - | H28: - | J28: DIKSHA | K28: 45814 | L28: PRATHEEBA | N28: IKBKG GENE (Medgenome report awaiting) | O28: 26-05-2025 | P28: Writeup available
A29: 8 | B29: MR.KAVIN NILAVAN R (26Y|M) | C29: WES | D29: GEN_T_2.0.spik_1094 | E29: AND25150014265 | F29: SUDHA RATHNA PRABHU MBBS,DNB,PHD | G29: 45967 | H29: 8 days | J29: VAMSHI | K29: 45826 | O29: 21/06/2025 | P29: Writeup available
A30: 9 | B30: LIYAN SAI 7M/M | C30: WES | D30: GEN_T_2.0.spik_1092 | E30: AND25020011504 | F30: CHIEF MINISTERS COMPREHENSIVE HEALTH INSURANCE SCHEME | G30: 45875 | H30: 5 days | J30: VAMSHI | K30: 45814 | L30: NAVEEN | O30: 21-06-2025
A31: 10 | B31: MR.VIJAYASIMHA (42Y|M) | C31: WES | D31: GEN_T_2.0.spik_1095 | E31: AND251R0003001 | F31: AIKYA FERTILITY AND RESEARCH CENTER - BANGALORE | G31: 13-06-2025 | H31: 10 days | J31: VAMSHI | K31: 45829 | O31: 24-06-2025 | P31: Writeup available
A32: 11 | B32: DR.PUNITHA KASHYAP (37Y|F) | C32: WES | D32: GEN_T_2.0.spik_1096 | E32: AND251R0003002 | F32: AIKYA FERTILITY AND RESEARCH CENTER - BANGALORE | G32: 13-06-2025 | H32: 10 days | J32: VAMSHI | K32: 45829 | O32: 24-06-2025 | P32: Writeup available
A33: 12 | B33: MRS.SHANTHA LAKSHMI M (38Y|F) | C33: WES | D33: GEN_T_2.0.spik_1097 | E33: AND25020010950 | F33: DECHAMMA K A MBBS DNB OBG | G33: 13-06-2025 | H33: 10 days | J33: DIKSHA | K33: 14/06/2025 | O33: 21-06-2025
A34: 13 | B34: MRS.PAVITHRA [1941] (30Y|F) | C34: WES | D34: GEN_T_2.0.spik_1098 | E34: AND25430000231 | F34: SRI CHAKRA FERTILITY - ASHOK NAGAR | G34: 13-06-2025 | H34: 10 days | O34: 18/06/2025
A35: 14 | B35: MASTER.SRITHAR(4YM) | C35: WES | D35: GEN_T_2.0.spik_1076 | E35: AND25020010066 | F35: CHIEF MINISTERS COMPREHENSIVE HEALTH INSURANCE SCHEME | G35: 13-06-2025 | H35: 10 days | J35: VAMSHI | K35: 45814 | L35: NAVEEN | O35: 45997 | P35: Writeup available
A36: 15 | B36: BABY.SAKTHI BALAN(4YM) | C36: WES | D36: GEN_T_2.0.spik_1110 | E36: AND25020011863 | F36: CHIEF MINISTERS COMPREHENSIVE HEALTH INSURANCE SCHEME | G36: 15-06-2025 | H36: 12 days | J36: DIKSHA | K36: 45844 | L36: PRATHEEBA | O36: 23/06/2024 | P36: Writeup available
A37: 16 | B37: MR.KARTHIKEYAN (UHID 7176685) (43Y|M) | C37: WES | D37: GEN_T_2.0.spik_1101 | E37: AND25150015045 | F37: HINDU MISSION HOSPITAL | G37: 14-06-2025 | H37: 11 days | J37: VAMSHI | K37: 45817 | L37: NAVEEN | O37: 20-06-2025
A38: 17 | B38: MR.VENKATA CHAITANYA REDDY G (29Y|M) | C38: WES | D38: GEN_T_2.0.spik_1102 | E38: AND25250000327 | F38: AMERICAN KIDNEY INSTITUTTE - VIJAYAWADA | G38: 14-06-2025 | H38: 11 days | J38: DIKSHA | K38: 45844 | O38: 20-06-2025
A39: 18 | B39: MR.KISHORE GOWTHAM RAJU (32Y|M) | C39: WES | D39: GEN_T_2.0.spik_1103 | E39: AND25630000527 | F39: M LAB SERVICES - T NAGAR | G39: 14-06-2025 | H39: 11 days | J39: VAMSHI | K39: 45815 | L39: NAVEEN | O39: 20-06-2025 | P39: Writeup available
A40: 19 | B40: MASTER.ASHIF (6Y|M) | C40: WES | D40: GEN_T_2.0.spik_1104 | E40: AND25020011505 | F40: CHIEF MINISTERS COMPREHENSIVE HEALTH INSURANCE SCHEME | G40: 15-06-2025 | H40: 12 days | J40: DIKSHA | K40: 45906 | O40: 21-06-2025 | P40: Writeup available
A41: 20 | B41: BABY.PADMAVATHY (4Y|F) | C41: WES | D41: GEN_T_2.0.spik_1105 | E41: AND25020011506 | F41: CHIEF MINISTERS COMPREHENSIVE HEALTH INSURANCE SCHEME | G41: 15-06-2025 | H41: 12 days | J41: VAMSHI | K41: 45815 | L41: Naveen | O41: 21-06-2025
A42: 21 | B42: MASTER.SANTHOSH KUMAR (11Y|M) | C42: WES | D42: GEN_T_2.0.spik_1106 | E42: AND25020011507 | F42: CHIEF MINISTERS COMPREHENSIVE HEALTH INSURANCE SCHEME | G42: 15-06-2025 | H42: 12 days | J42: DIKSHA | K42: 45844 | L42: PRATHEEBA | O42: 45967
A43: 22 | B43: BABY.KIRTHIK (10M|M) | C43: WES | D43: GEN_T_2.0.spik_1107 | E43: AND25020011563 | F43: CHIEF MINISTERS COMPREHENSIVE HEALTH INSURANCE SCHEME | G43: 15-06-2025 | H43: 12 days | J43: VAMSHI | K43: 45817 | L43: NAVEEN | O43: 45695
A44: 23 | B44: MISS.KHUSHBOO JEETUKUMAR NIRANJKARI (13YF) | C44: CES | D44: GEN_T_2.0.spik_1108 | E44: AND25750002265 | F44: SUNANDA FERTILITY CLINIC - KOLHAPUR | G44: 15-06-2025 | H44: 12 days | J44: VAMSHI | K44: 45820 | L44: PRATHEEBA | N44: CAH MLPA (MEDGENOME) | O44: 45695 | P44: Writeup available
...

Sheet TAT_HELPER
A1: =IFERROR(__xludf.DUMMYFUNCTION("{IMPORTRANGE(""1VtZVtwNEQ1lYZ8oSh9K6KBuaAtjNhASA7BRnHiq7nkE"",""JANUARY!G2:J"");IMPORTRANGE(""1VtZVtwNEQ1lYZ8oSh9K6KBuaAtjNhASA7BRnHiq7nkE"",""FEBRUARY!G2:J"");IMPORTRANGE(""1VtZVtwNEQ1lYZ8oSh9K6KBuaAtjNhASA7BRnHiq7nkE"",""MARCH!G2:J"");IMPORTRANGE(""1VtZ"&"VtwNEQ1lYZ8oSh9K6KBuaAtjNhASA7BRnHiq7nkE"",""APRIL!G2:J"");IMPORTRANGE(""1VtZVtwNEQ1lYZ8oSh9K6KBuaAtjNhASA7BRnHiq7nkE"",""MAY!G2:J"");IMPORTRANGE(""1VtZVtwNEQ1lYZ8oSh9K6KBuaAtjNhASA7BRnHiq7nkE"",""JUNE!G2:J"");IMPORTRANGE(""1VtZVtwNEQ1lYZ8oSh9K6KBuaAtjNhA"&"SA7BRnHiq7nkE"",""JULY!G2:J"")}"),"ANDERSON ID") -> ANDERSON ID | B1: =IFERROR(__xludf.DUMMYFUNCTION("""COMPUTED_VALUE"""),"CATEGORY") -> CATEGORY | C1: =IFERROR(__xludf.DUMMYFUNCTION("""COMPUTED_VALUE"""),"RAW DATA RECEIVED") -> RAW DATA RECEIVED | D1: =IFERROR(__xludf.DUMMYFUNCTION("""COMPUTED_VALUE"""),"ANDERSON TAT") -> ANDERSON TAT
A2: =IFERROR(__xludf.DUMMYFUNCTION("""COMPUTED_VALUE"""),"AND25020063505") -> AND25020063505 | B2: =IFERROR(__xludf.DUMMYFUNCTION("""COMPUTED_VALUE"""),"WES+WMGS") -> WES+WMGS | C2: =IFERROR(__xludf.DUMMYFUNCTION("""COMPUTED_VALUE"""),46031.0) -> 46031 | D2: =IFERROR(__xludf.DUMMYFUNCTION("""COMPUTED_VALUE"""),46054.0) -> 46054
A3: =IFERROR(__xludf.DUMMYFUNCTION("""COMPUTED_VALUE"""),"AND25020063507") -> AND25020063507 | B3: =IFERROR(__xludf.DUMMYFUNCTION("""COMPUTED_VALUE"""),"WES+WMGS") -> WES+WMGS | C3: =IFERROR(__xludf.DUMMYFUNCTION("""COMPUTED_VALUE"""),46031.0) -> 46031 | D3: =IFERROR(__xludf.DUMMYFUNCTION("""COMPUTED_VALUE"""),46054.0) -> 46054
A4: =IFERROR(__xludf.DUMMYFUNCTION("""COMPUTED_VALUE"""),"AND25410032666") -> AND25410032666 | B4: =IFERROR(__xludf.DUMMYFUNCTION("""COMPUTED_VALUE"""),"WES+WMGS") -> WES+WMGS | C4: =IFERROR(__xludf.DUMMYFUNCTION("""COMPUTED_VALUE"""),46031.0) -> 46031 | D4: =IFERROR(__xludf.DUMMYFUNCTION("""COMPUTED_VALUE"""),46053.0) -> 46053
A5: =IFERROR(__xludf.DUMMYFUNCTION("""COMPUTED_VALUE"""),"ADB0000018249") -> ADB0000018249 | B5: =IFERROR(__xludf.DUMMYFUNCTION("""COMPUTED_VALUE"""),"WES") -> WES | C5: =IFERROR(__xludf.DUMMYFUNCTION("""COMPUTED_VALUE"""),46031.0) -> 46031 | D5: =IFERROR(__xludf.DUMMYFUNCTION("""COMPUTED_VALUE"""),46054.0) -> 46054
A6: =IFERROR(__xludf.DUMMYFUNCTION("""COMPUTED_VALUE"""),"ADB0000018250") -> ADB0000018250 | B6: =IFERROR(__xludf.DUMMYFUNCTION("""COMPUTED_VALUE"""),"WES") -> WES | C6: =IFERROR(__xludf.DUMMYFUNCTION("""COMPUTED_VALUE"""),46031.0) -> 46031 | D6: =IFERROR(__xludf.DUMMYFUNCTION("""COMPUTED_VALUE"""),46054.0) -> 46054
A7: =IFERROR(__xludf.DUMMYFUNCTION("""COMPUTED_VALUE"""),"ADB0000018299") -> ADB0000018299 | B7: =IFERROR(__xludf.DUMMYFUNCTION("""COMPUTED_VALUE"""),"WES") -> WES | C7: =IFERROR(__xludf.DUMMYFUNCTION("""COMPUTED_VALUE"""),46031.0) -> 46031 | D7: =IFERROR(__xludf.DUMMYFUNCTION("""COMPUTED_VALUE"""),46054.0) -> 46054
A8: =IFERROR(__xludf.DUMMYFUNCTION("""COMPUTED_VALUE"""),"DCC0000001985") -> DCC0000001985 | B8: =IFERROR(__xludf.DUMMYFUNCTION("""COMPUTED_VALUE"""),"WES") -> WES | C8: =IFERROR(__xludf.DUMMYFUNCTION("""COMPUTED_VALUE"""),46031.0) -> 46031 | D8: =IFERROR(__xludf.DUMMYFUNCTION("""COMPUTED_VALUE"""),46054.0) -> 46054
A9: =IFERROR(__xludf.DUMMYFUNCTION("""COMPUTED_VALUE"""),"AND25630004223") -> AND25630004223 | B9: =IFERROR(__xludf.DUMMYFUNCTION("""COMPUTED_VALUE"""),"WES") -> WES | C9: =IFERROR(__xludf.DUMMYFUNCTION("""COMPUTED_VALUE"""),46031.0) -> 46031 | D9: =IFERROR(__xludf.DUMMYFUNCTION("""COMPUTED_VALUE"""),46045.0) -> 46045
A10: =IFERROR(__xludf.DUMMYFUNCTION("""COMPUTED_VALUE"""),"AND25630004224") -> AND25630004224 | B10: =IFERROR(__xludf.DUMMYFUNCTION("""COMPUTED_VALUE"""),"WES") -> WES | C10: =IFERROR(__xludf.DUMMYFUNCTION("""COMPUTED_VALUE"""),46031.0) -> 46031 | D10: =IFERROR(__xludf.DUMMYFUNCTION("""COMPUTED_VALUE"""),46045.0) -> 46045
A11: =IFERROR(__xludf.DUMMYFUNCTION("""COMPUTED_VALUE"""),"AND25630004225") -> AND25630004225 | B11: =IFERROR(__xludf.DUMMYFUNCTION("""COMPUTED_VALUE"""),"WES") -> WES | C11: =IFERROR(__xludf.DUMMYFUNCTION("""COMPUTED_VALUE"""),46031.0) -> 46031 | D11: =IFERROR(__xludf.DUMMYFUNCTION("""COMPUTED_VALUE"""),46045.0) -> 46045
A12: =IFERROR(__xludf.DUMMYFUNCTION("""COMPUTED_VALUE"""),"AND25630004226") -> AND25630004226 | B12: =IFERROR(__xludf.DUMMYFUNCTION("""COMPUTED_VALUE"""),"WES") -> WES | C12: =IFERROR(__xludf.DUMMYFUNCTION("""COMPUTED_VALUE"""),46031.0) -> 46031 | D12: =IFERROR(__xludf.DUMMYFUNCTION("""COMPUTED_VALUE"""),46045.0) -> 46045
A13: =IFERROR(__xludf.DUMMYFUNCTION("""COMPUTED_VALUE"""),"AND25630004227") -> AND25630004227 | B13: =IFERROR(__xludf.DUMMYFUNCTION("""COMPUTED_VALUE"""),"WES") -> WES | C13: =IFERROR(__xludf.DUMMYFUNCTION("""COMPUTED_VALUE"""),46031.0) -> 46031 | D13: =IFERROR(__xludf.DUMMYFUNCTION("""COMPUTED_VALUE"""),46045.0) -> 46045
A14: =IFERROR(__xludf.DUMMYFUNCTION("""COMPUTED_VALUE"""),"AND25630004228") -> AND25630004228 | B14: =IFERROR(__xludf.DUMMYFUNCTION("""COMPUTED_VALUE"""),"WES") -> WES | C14: =IFERROR(__xludf.DUMMYFUNCTION("""COMPUTED_VALUE"""),46031.0) -> 46031 | D14: =IFERROR(__xludf.DUMMYFUNCTION("""COMPUTED_VALUE"""),46045.0) -> 46045
A15: =IFERROR(__xludf.DUMMYFUNCTION("""COMPUTED_VALUE"""),"AND25630004229") -> AND25630004229 | B15: =IFERROR(__xludf.DUMMYFUNCTION("""COMPUTED_VALUE"""),"WES") -> WES | C15: =IFERROR(__xludf.DUMMYFUNCTION("""COMPUTED_VALUE"""),46031.0) -> 46031 | D15: =IFERROR(__xludf.DUMMYFUNCTION("""COMPUTED_VALUE"""),46045.0) -> 46045
A16: =IFERROR(__xludf.DUMMYFUNCTION("""COMPUTED_VALUE"""),"AND25630004230") -> AND25630004230 | B16: =IFERROR(__xludf.DUMMYFUNCTION("""COMPUTED_VALUE"""),"WES") -> WES | C16: =IFERROR(__xludf.DUMMYFUNCTION("""COMPUTED_VALUE"""),46031.0) -> 46031 | D16: =IFERROR(__xludf.DUMMYFUNCTION("""COMPUTED_VALUE"""),46045.0) -> 46045
A17: =IFERROR(__xludf.DUMMYFUNCTION("""COMPUTED_VALUE"""),"AND25630004231") -> AND25630004231 | B17: =IFERROR(__xludf.DUMMYFUNCTION("""COMPUTED_VALUE"""),"WES") -> WES | C17: =IFERROR(__xludf.DUMMYFUNCTION("""COMPUTED_VALUE"""),46031.0) -> 46031 | D17: =IFERROR(__xludf.DUMMYFUNCTION("""COMPUTED_VALUE"""),46045.0) -> 46045
A18: =IFERROR(__xludf.DUMMYFUNCTION("""COMPUTED_VALUE"""),"AND25630004216") -> AND25630004216 | B18: =IFERROR(__xludf.DUMMYFUNCTION("""COMPUTED_VALUE"""),"WES+WMGS") -> WES+WMGS | C18: =IFERROR(__xludf.DUMMYFUNCTION("""COMPUTED_VALUE"""),46031.0) -> 46031 | D18: =IFERROR(__xludf.DUMMYFUNCTION("""COMPUTED_VALUE"""),46045.0) -> 46045
A19: =IFERROR(__xludf.DUMMYFUNCTION("""COMPUTED_VALUE"""),"AND25630004212") -> AND25630004212 | B19: =IFERROR(__xludf.DUMMYFUNCTION("""COMPUTED_VALUE"""),"WES") -> WES | C19: =IFERROR(__xludf.DUMMYFUNCTION("""COMPUTED_VALUE"""),46031.0) -> 46031 | D19: =IFERROR(__xludf.DUMMYFUNCTION("""COMPUTED_VALUE"""),46046.0) -> 46046
A20: =IFERROR(__xludf.DUMMYFUNCTION("""COMPUTED_VALUE"""),"AND25630004213") -> AND25630004213 | B20: =IFERROR(__xludf.DUMMYFUNCTION("""COMPUTED_VALUE"""),"WES") -> WES | C20: =IFERROR(__xludf.DUMMYFUNCTION("""COMPUTED_VALUE"""),46031.0) -> 46031 | D20: =IFERROR(__xludf.DUMMYFUNCTION("""COMPUTED_VALUE"""),46046.0) -> 46046
A21: =IFERROR(__xludf.DUMMYFUNCTION("""COMPUTED_VALUE"""),"AND25630004214") -> AND25630004214 | B21: =IFERROR(__xludf.DUMMYFUNCTION("""COMPUTED_VALUE"""),"WES") -> WES | C21: =IFERROR(__xludf.DUMMYFUNCTION("""COMPUTED_VALUE"""),46031.0) -> 46031 | D21: =IFERROR(__xludf.DUMMYFUNCTION("""COMPUTED_VALUE"""),46046.0) -> 46046
A22: =IFERROR(__xludf.DUMMYFUNCTION("""COMPUTED_VALUE"""),"AND25630004215") -> AND25630004215 | B22: =IFERROR(__xludf.DUMMYFUNCTION("""COMPUTED_VALUE"""),"WES") -> WES | C22: =IFERROR(__xludf.DUMMYFUNCTION("""COMPUTED_VALUE"""),46031.0) -> 46031 | D22: =IFERROR(__xludf.DUMMYFUNCTION("""COMPUTED_VALUE"""),46046.0) -> 46046
A23: =IFERROR(__xludf.DUMMYFUNCTION("""COMPUTED_VALUE"""),"AND25630004217") -> AND25630004217 | B23: =IFERROR(__xludf.DUMMYFUNCTION("""COMPUTED_VALUE"""),"WES") -> WES | C23: =IFERROR(__xludf.DUMMYFUNCTION("""COMPUTED_VALUE"""),46031.0) -> 46031 | D23: =IFERROR(__xludf.DUMMYFUNCTION("""COMPUTED_VALUE"""),46046.0) -> 46046
A24: =IFERROR(__xludf.DUMMYFUNCTION("""COMPUTED_VALUE"""),"ADB0000018649") -> ADB0000018649 | B24: =IFERROR(__xludf.DUMMYFUNCTION("""COMPUTED_VALUE"""),"WES") -> WES | C24: =IFERROR(__xludf.DUMMYFUNCTION("""COMPUTED_VALUE"""),46031.0) -> 46031 | D24: =IFERROR(__xludf.DUMMYFUNCTION("""COMPUTED_VALUE"""),46056.0) -> 46056
A25: =IFERROR(__xludf.DUMMYFUNCTION("""COMPUTED_VALUE"""),"ADH0000007463") -> ADH0000007463 | B25: =IFERROR(__xludf.DUMMYFUNCTION("""COMPUTED_VALUE"""),"WES") -> WES | C25: =IFERROR(__xludf.DUMMYFUNCTION("""COMPUTED_VALUE"""),46031.0) -> 46031 | D25: =IFERROR(__xludf.DUMMYFUNCTION("""COMPUTED_VALUE"""),46053.0) -> 46053
A26: =IFERROR(__xludf.DUMMYFUNCTION("""COMPUTED_VALUE"""),"ADB0000018103") -> ADB0000018103 | B26: =IFERROR(__xludf.DUMMYFUNCTION("""COMPUTED_VALUE"""),"SINGLE GENE – FULL GENE SEQUENCING BY NGS") -> SINGLE GENE – FULL GENE SEQUENCING BY NGS | C26: =IFERROR(__xludf.DUMMYFUNCTION("""COMPUTED_VALUE"""),46031.0) -> 46031 | D26: =IFERROR(__xludf.DUMMYFUNCTION("""COMPUTED_VALUE"""),46054.0) -> 46054
A27: =IFERROR(__xludf.DUMMYFUNCTION("""COMPUTED_VALUE"""),"ADB0000018232") -> ADB0000018232 | B27: =IFERROR(__xludf.DUMMYFUNCTION("""COMPUTED_VALUE"""),"FEMALE INFERTILITY NGS PANEL") -> FEMALE INFERTILITY NGS PANEL | C27: =IFERROR(__xludf.DUMMYFUNCTION("""COMPUTED_VALUE"""),46031.0) -> 46031 | D27: =IFERROR(__xludf.DUMMYFUNCTION("""COMPUTED_VALUE"""),46055.0) -> 46055
A28: =IFERROR(__xludf.DUMMYFUNCTION("""COMPUTED_VALUE"""),"ADB0000018205") -> ADB0000018205 | B28: =IFERROR(__xludf.DUMMYFUNCTION("""COMPUTED_VALUE"""),"FEMALE INFERTILITY NGS PANEL") -> FEMALE INFERTILITY NGS PANEL | C28: =IFERROR(__xludf.DUMMYFUNCTION("""COMPUTED_VALUE"""),46031.0) -> 46031 | D28: =IFERROR(__xludf.DUMMYFUNCTION("""COMPUTED_VALUE"""),46055.0) -> 46055
A29: =IFERROR(__xludf.DUMMYFUNCTION("""COMPUTED_VALUE"""),"DCC0000002044") -> DCC0000002044 | B29: =IFERROR(__xludf.DUMMYFUNCTION("""COMPUTED_VALUE"""),"WES") -> WES | C29: =IFERROR(__xludf.DUMMYFUNCTION("""COMPUTED_VALUE"""),46031.0) -> 46031 | D29: =IFERROR(__xludf.DUMMYFUNCTION("""COMPUTED_VALUE"""),30.0) -> 30
A30: =IFERROR(__xludf.DUMMYFUNCTION("""COMPUTED_VALUE"""),"AND25720033575") -> AND25720033575 | B30: =IFERROR(__xludf.DUMMYFUNCTION("""COMPUTED_VALUE"""),"WES") -> WES | C30: =IFERROR(__xludf.DUMMYFUNCTION("""COMPUTED_VALUE"""),46031.0) -> 46031 | D30: =IFERROR(__xludf.DUMMYFUNCTION("""COMPUTED_VALUE"""),46056.0) -> 46056
A31: =IFERROR(__xludf.DUMMYFUNCTION("""COMPUTED_VALUE"""),"AND25720033393") -> AND25720033393 | B31: =IFERROR(__xludf.DUMMYFUNCTION("""COMPUTED_VALUE"""),"FEMALE INFERTILITY NGS PANEL") -> FEMALE INFERTILITY NGS PANEL | C31: =IFERROR(__xludf.DUMMYFUNCTION("""COMPUTED_VALUE"""),46031.0) -> 46031 | D31: =IFERROR(__xludf.DUMMYFUNCTION("""COMPUTED_VALUE"""),30.0) -> 30
A32: =IFERROR(__xludf.DUMMYFUNCTION("""COMPUTED_VALUE"""),"AND25020063950") -> AND25020063950 | B32: =IFERROR(__xludf.DUMMYFUNCTION("""COMPUTED_VALUE"""),"WES+WMGS") -> WES+WMGS | C32: =IFERROR(__xludf.DUMMYFUNCTION("""COMPUTED_VALUE"""),46034.0) -> 46034 | D32: =IFERROR(__xludf.DUMMYFUNCTION("""COMPUTED_VALUE"""),46057.0) -> 46057
A33: =IFERROR(__xludf.DUMMYFUNCTION("""COMPUTED_VALUE"""),"AND25020063725") -> AND25020063725 | B33: =IFERROR(__xludf.DUMMYFUNCTION("""COMPUTED_VALUE"""),"WES+WMGS") -> WES+WMGS | C33: =IFERROR(__xludf.DUMMYFUNCTION("""COMPUTED_VALUE"""),46034.0) -> 46034 | D33: =IFERROR(__xludf.DUMMYFUNCTION("""COMPUTED_VALUE"""),46055.0) -> 46055
A34: =IFERROR(__xludf.DUMMYFUNCTION("""COMPUTED_VALUE"""),"DCC0000002016") -> DCC0000002016 | B34: =IFERROR(__xludf.DUMMYFUNCTION("""COMPUTED_VALUE"""),"WES+WMGS") -> WES+WMGS | C34: =IFERROR(__xludf.DUMMYFUNCTION("""COMPUTED_VALUE"""),46034.0) -> 46034 | D34: =IFERROR(__xludf.DUMMYFUNCTION("""COMPUTED_VALUE"""),46055.0) -> 46055
A35: =IFERROR(__xludf.DUMMYFUNCTION("""COMPUTED_VALUE"""),"AND25020063606") -> AND25020063606 | B35: =IFERROR(__xludf.DUMMYFUNCTION("""COMPUTED_VALUE"""),"WES+WMGS") -> WES+WMGS | C35: =IFERROR(__xludf.DUMMYFUNCTION("""COMPUTED_VALUE"""),46034.0) -> 46034 | D35: =IFERROR(__xludf.DUMMYFUNCTION("""COMPUTED_VALUE"""),46055.0) -> 46055
A36: =IFERROR(__xludf.DUMMYFUNCTION("""COMPUTED_VALUE"""),"ADH0000007784") -> ADH0000007784 | B36: =IFERROR(__xludf.DUMMYFUNCTION("""COMPUTED_VALUE"""),"WES") -> WES | C36: =IFERROR(__xludf.DUMMYFUNCTION("""COMPUTED_VALUE"""),46034.0) -> 46034 | D36: =IFERROR(__xludf.DUMMYFUNCTION("""COMPUTED_VALUE"""),46055.0) -> 46055
A37: =IFERROR(__xludf.DUMMYFUNCTION("""COMPUTED_VALUE"""),"ADH0000008175") -> ADH0000008175 | B37: =IFERROR(__xludf.DUMMYFUNCTION("""COMPUTED_VALUE"""),"WES") -> WES | C37: =IFERROR(__xludf.DUMMYFUNCTION("""COMPUTED_VALUE"""),46034.0) -> 46034 | D37: =IFERROR(__xludf.DUMMYFUNCTION("""COMPUTED_VALUE"""),46057.0) -> 46057
A38: =IFERROR(__xludf.DUMMYFUNCTION("""COMPUTED_VALUE"""),"ADH0000008176") -> ADH0000008176 | B38: =IFERROR(__xludf.DUMMYFUNCTION("""COMPUTED_VALUE"""),"WES") -> WES | C38: =IFERROR(__xludf.DUMMYFUNCTION("""COMPUTED_VALUE"""),46034.0) -> 46034 | D38: =IFERROR(__xludf.DUMMYFUNCTION("""COMPUTED_VALUE"""),46057.0) -> 46057
A39: =IFERROR(__xludf.DUMMYFUNCTION("""COMPUTED_VALUE"""),"ADH0000008177") -> ADH0000008177 | B39: =IFERROR(__xludf.DUMMYFUNCTION("""COMPUTED_VALUE"""),"WES") -> WES | C39: =IFERROR(__xludf.DUMMYFUNCTION("""COMPUTED_VALUE"""),46034.0) -> 46034 | D39: =IFERROR(__xludf.DUMMYFUNCTION("""COMPUTED_VALUE"""),46057.0) -> 46057
A40: =IFERROR(__xludf.DUMMYFUNCTION("""COMPUTED_VALUE"""),"ADB0000018581") -> ADB0000018581 | B40: =IFERROR(__xludf.DUMMYFUNCTION("""COMPUTED_VALUE"""),"FEMALE INFERTILITY NGS PANEL") -> FEMALE INFERTILITY NGS PANEL | C40: =IFERROR(__xludf.DUMMYFUNCTION("""COMPUTED_VALUE"""),46034.0) -> 46034 | D40: =IFERROR(__xludf.DUMMYFUNCTION("""COMPUTED_VALUE"""),46058.0) -> 46058
...
